Workbook

Sheet Dashboard
A1: FINANCIAL BUDGET & EXPENSE DASHBOARD
A3: 2025 | Synthetic practice dataset | Currency: INR
A4: Month Filter | B4: All | D4: Select a month to filter KPI cards.
A6: TOTAL EXPENSES | D6: SAVINGS CONTRIBUTIONS | G6: TRANSACTIONS | J6: AVG. TRANSACTION
A7: =IF($B$4="All",SUMIFS(Clean_Data!$I$2:$I$481,Clean_Data!$D$2:$D$481,"Expense"),SUMIFS(Clean_Data!$I$2:$I$481,Clean_Data!$D$2:$D$481,"Expense",Clean_Data!$C$2:$C$481,$B$4)) | D7: =IF($B$4="All",SUMIFS(Clean_Data!$I$2:$I$481,Clean_Data!$D$2:$D$481,"Savings"),SUMIFS(Clean_Data!$I$2:$I$481,Clean_Data!$D$2:$D$481,"Savings",Clean_Data!$C$2:$C$481,$B$4)) | G7: =IF($B$4="All",COUNTA(Clean_Data!$A$2:$A$481),COUNTIF(Clean_Data!$C$2:$C$481,$B$4)) | J7: =IFERROR(IF($B$4="All",AVERAGEIFS(Clean_Data!$I$2:$I$481,Clean_Data!$D$2:$D$481,"Expense"),AVERAGEIFS(Clean_Data!$I$2:$I$481,Clean_Data!$D$2:$D$481,"Expense",Clean_Data!$C$2:$C$481,$B$4)),0)
A42: Note: KPI cards respond to the month selector; charts show full-year summaries.

Sheet Raw_Data
A1: Transaction_ID | B1: Date | C1: Month | D1: Transaction_Type | E1: Category | F1: Subcategory | G1: Description | H1: Payment_Method | I1: Amount_INR
A2: TXN-0001 | B2: 2025-05-24 | C2: May-2025 | D2: Expense | E2: Food | F2: Coffee | G2: Coffee transaction | H2: Debit Card | I2: 2238.97
A3: TXN-0002 | B3: 2025-08-25 | C3: Aug-2025 | D3: Expense | E3: Health | F3: Medical Visit | G3: Medical Visit transaction | H3: Cash | I3: 470.31
A4: TXN-0003 | B4: 2025-09-23 | C4: Sep-2025 | D4: Savings | E4: Savings | F4: Emergency Fund | G4: Emergency Fund transaction | H4: Cash | I4: 1088.4
A5: TXN-0004 | B5: 2025-01-14 | C5: Jan-2025 | D5: Expense | E5: Entertainment | F5: Movies | G5: Movies transaction | H5: Cash | I5: 2575.9
A6: TXN-0005 | B6: 2025-10-11 | C6: Oct-2025 | D6: Expense | E6: Entertainment | F6: Streaming | G6: Streaming transaction | H6: Credit Card | I6: 3871.03
A7: TXN-0006 | B7: 2025-10-19 | C7: Oct-2025 | D7: Expense | E7: Travel | F7: Hotel | G7: Hotel transaction | H7: UPI | I7: 3575.05
A8: TXN-0007 | B8: 2025-08-26 | C8: Aug-2025 | D8: Expense | E8: Shopping | F8: Electronics | G8: Electronics transaction | H8: Debit Card | I8: 4286.5
A9: TXN-0008 | B9: 2025-01-13 | C9: Jan-2025 | D9: Expense | E9: Utilities | F9: Water Bill | G9: Water Bill transaction | H9: UPI | I9: 4193.65
A10: TXN-0009 | B10: 2025-05-02 | C10: May-2025 | D10: Savings | E10: Savings | F10: Emergency Fund | G10: Emergency Fund transaction | H10: UPI | I10: 2719.37
A11: TXN-0010 | B11: 2025-12-14 | C11: Dec-2025 | D11: Expense | E11: Food | F11: Coffee | G11: Coffee transaction | H11: Debit Card | I11: 4378.04
A12: TXN-0011 | B12: 2025-10-12 | C12: Oct-2025 | D12: Expense | E12: Transport | F12: Vehicle Maintenance | G12: Vehicle Maintenance transaction | H12: Cash | I12: 2160.82
A13: TXN-0012 | B13: 2025-12-29 | C13: Dec-2025 | D13: Savings | E13: Savings | F13: Emergency Fund | G13: Emergency Fund transaction | H13: UPI | I13: 2215.4
... A40: TXN-0039 | B40: 2025-09-11 | C40: Sep-2025 | D40: Expense | E40: Shopping | F40: Electronics | G40: Electronics transaction | H40: Debit Card | I40: 3823.46
A41: TXN-0040 | B41: 2025-12-28 | C41: Dec-2025 | D41: Expense | E41: Transport | F41: Ride Share | H41: Credit Card | I41: 1072.89
A42: TXN-0041 | B42: 2025-04-17 | C42: Apr-2025 | D42: Expense | E42: Utilities | F42: Water Bill | G42: Water Bill transaction | H42: UPI | I42: 3539.29
A43: TXN-0042 | B43: 2025-09-14 | C43: Sep-2025 | D43: Expense | E43: Entertainment | F43: Streaming | G43: Streaming transaction | H43: Cash | I43: 2886.46
A44: TXN-0043 | B44: 2025-04-20 | C44: Apr-2025 | D44: Expense | E44: Transport | F44: Vehicle Maintenance | G44: Vehicle Maintenance transaction | H44: Credit Card | I44: 2052.34
A45: TXN-0044 | B45: 2025-04-11 | C45: Apr-2025 | D45: Savings | E45: Savings | F45: Emergency Fund | G45: Emergency Fund transaction | H45: UPI | I45: 1696.99
A46: TXN-0045 | B46: 2025-12-09 | C46: Dec-2025 | D46: Expense | E46: Shopping | F46: Clothing | G46: Clothing transaction | H46: UPI | I46: 3308.62
A47: TXN-0046 | B47: 2025-05-31 | C47: May-2025 | D47: Expense | E47: Entertainment | F47: Streaming | G47: Streaming transaction | H47: Bank Transfer | I47: 1090.82
A48: TXN-0047 | B48: 2025-09-17 | C48: Sep-2025 | D48: Expense | E48: Shopping | F48: Clothing | G48: Clothing transaction | H48: Bank Transfer | I48: 4341.67
A49: TXN-0048 | B49: 2025-03-20 | C49: Mar-2025 | D49: Expense | E49: Entertainment | F49: Movies | G49: Movies transaction | H49: Debit Card | I49: 1263.76
A50: TXN-0049 | B50: 2025-05-01 | C50: May-2025 | D50: Expense | E50: Health | F50: Medical Visit | G50: Medical Visit transaction | H50: Cash | I50: 205.56
A51: TXN-0050 | B51: 2025-08-18 | C51: Aug-2025 | D51: Expense | E51: Travel | F51: Flights | G51: Flights transaction | H51: UPI | I51: 2161.44
A52: TXN-0051 | B52: 2025-03-02 | C52: Mar-2025 | D52: Savings | E52: Savings | F52: Emergency Fund | G52: Emergency Fund transaction | H52: UPI | I52: 4303.53
A53: TXN-0052 | B53: 2025-01-28 | C53: Jan-2025 | D53: Expense | E53: Shopping | F53: Clothing | G53: Clothing transaction | H53: UPI | I53: 1296.96
... A281: TXN-0280 | B281: 2025-07-05 | C281: Jul-2025 | D281: Expense | E281: Utilities | F281: Mobile Bill | G281: Mobile Bill transaction | H281: Debit Card | I281: 413.53
A282: TXN-0281 | B282: 2025-12-19 | C282: Dec-2025 | D282: Expense | E282: Health | F282: Pharmacy | H282: Credit Card | I282: 4216.01
A283: TXN-0282 | B283: 2025-08-07 | C283: Aug-2025 | D283: Expense | E283: Housing | F283: Rent | G283: Rent transaction | H283: Debit Card | I283: 10011.37
A284: TXN-0283 | B284: 2025-10-14 | C284: Oct-2025 | D284: Expense | E284: Transport | F284: Vehicle Maintenance | G284: Vehicle Maintenance transaction | H284: Debit Card | I284: 2099.6
A285: TXN-0284 | B285: 2025-09-01 | C285: Sep-2025 | D285: Expense | E285: Education | F285: Books | G285: Books transaction | H285: Debit Card | I285: 670.64
A286: TXN-0285 | B286: 2025-08-10 | C286: Aug-2025 | D286: Expense | E286: Education | F286: Software | G286: Software transaction | H286: Cash | I286: 2079.71
A287: TXN-0286 | B287: 2025-09-17 | C287: Sep-2025 | D287: Expense | E287: Education | F287: Books | G287: Books transaction | H287: Debit Card | I287: 2621.14
A288: TXN-0287 | B288: 2025-11-09 | C288: Nov-2025 | D288: Expense | E288: Shopping | F288: Clothing | G288: Clothing transaction | H288: Cash | I288: 3575.86
A289: TXN-0288 | B289: 2025-09-26 | C289: Sep-2025 | D289: Expense | E289: Shopping | F289: Personal Care | G289: Personal Care transaction | H289: Cash | I289: 3135.05
A290: TXN-0289 | B290: 2025-07-16 | C290: Jul-2025 | D290: Expense | E290: Housing | F290: Home Supplies | G290: Home Supplies transaction | H290: Credit Card | I290: 1639.29
A291: TXN-0290 | B291: 2025-10-19 | C291: Oct-2025 | D291: Expense | E291: Education | F291: Books | G291: Books transaction | H291: Cash | I291: 2688.17
A292: TXN-0291 | B292: 2025-09-09 | C292: Sep-2025 | D292: Expense | E292: Transport | F292: Ride Share | G292: Ride Share transaction | H292: Credit Card | I292: 4183.01
A293: TXN-0292 | B293: 2025-04-14 | C293: Apr-2025 | D293: Expense | E293: Entertainment | F293: Events | G293: Events transaction | H293: Bank Transfer | I293: 3834.17
...

Sheet Clean_Data
A1: Transaction_ID | B1: Date | C1: Month | D1: Transaction_Type | E1: Category | F1: Subcategory | G1: Description | H1: Payment_Method | I1: Amount_INR | J1: Budgeted_Amount_INR | K1: Budget_Variance_INR | L1: Budget_Status
A2: TXN-0001 | B2: 2025-05-24 | C2: May-2025 | D2: Expense | E2: Food | F2: Coffee | G2: Coffee transaction | H2: Debit Card | I2: 2238.97 | J2: 7500 | K2: 5261.03 | L2: Within Budget
A3: TXN-0002 | B3: 2025-08-25 | C3: Aug-2025 | D3: Expense | E3: Health | F3: Medical Visit | G3: Medical Visit transaction | H3: Cash | I3: 470.31 | J3: 1800 | K3: 1329.69 | L3: Within Budget
A4: TXN-0003 | B4: 2025-09-23 | C4: Sep-2025 | D4: Savings | E4: Savings | F4: Emergency Fund | G4: Emergency Fund transaction | H4: Cash | I4: 1088.4 | J4: 5000 | K4: 3911.6 | L4: Savings
A5: TXN-0004 | B5: 2025-01-14 | C5: Jan-2025 | D5: Expense | E5: Entertainment | F5: Movies | G5: Movies transaction | H5: Cash | I5: 2575.9 | J5: 1500 | K5: -1075.9 | L5: Over Transaction Budget
A6: TXN-0005 | B6: 2025-10-11 | C6: Oct-2025 | D6: Expense | E6: Entertainment | F6: Streaming | G6: Streaming transaction | H6: Credit Card | I6: 3871.03 | J6: 1500 | K6: -2371.03 | L6: Over Transaction Budget
A7: TXN-0006 | B7: 2025-10-19 | C7: Oct-2025 | D7: Expense | E7: Travel | F7: Hotel | G7: Hotel transaction | H7: UPI | I7: 3575.05 | J7: 2500 | K7: -1075.05 | L7: Over Transaction Budget
A8: TXN-0007 | B8: 2025-08-26 | C8: Aug-2025 | D8: Expense | E8: Shopping | F8: Electronics | G8: Electronics transaction | H8: Debit Card | I8: 4286.5 | J8: 3000 | K8: -1286.5 | L8: Over Transaction Budget
A9: TXN-0008 | B9: 2025-01-13 | C9: Jan-2025 | D9: Expense | E9: Utilities | F9: Water Bill | G9: Water Bill transaction | H9: UPI | I9: 4193.65 | J9: 1800 | K9: -2393.65 | L9: Over Transaction Budget
A10: TXN-0009 | B10: 2025-05-02 | C10: May-2025 | D10: Savings | E10: Savings | F10: Emergency Fund | G10: Emergency Fund transaction | H10: UPI | I10: 2719.37 | J10: 5000 | K10: 2280.63 | L10: Savings
A11: TXN-0010 | B11: 2025-12-14 | C11: Dec-2025 | D11: Expense | E11: Food | F11: Coffee | G11: Coffee transaction | H11: Debit Card | I11: 4378.04 | J11: 7500 | K11: 3121.96 | L11: Within Budget
A12: TXN-0011 | B12: 2025-10-12 | C12: Oct-2025 | D12: Expense | E12: Transport | F12: Vehicle Maintenance | G12: Vehicle Maintenance transaction | H12: Cash | I12: 2160.82 | J12: 3500 | K12: 1339.18 | L12: Within Budget
A13: TXN-0012 | B13: 2025-12-29 | C13: Dec-2025 | D13: Savings | E13: Savings | F13: Emergency Fund | G13: Emergency Fund transaction | H13: UPI | I13: 2215.4 | J13: 5000 | K13: 2784.6 | L13: Savings
... A481: TXN-0480 | B481: 2025-06-25 | C481: Jun-2025 | D481: Expense | E481: Transport | F481: Public Transport | G481: Public Transport transaction | H481: Bank Transfer | I481: 2443.27 | J481: 3500 | K481: 1056.73 | L481: Within Budget

Sheet Budgets
A1: Category | B1: Monthly_Budget_INR
A2: Housing | B2: 15000
A3: Food | B3: 7500
A4: Transport | B4: 3500
A5: Utilities | B5: 1800
A6: Health | B6: 1800
A7: Shopping | B7: 3000
A8: Entertainment | B8: 1500
A9: Education | B9: 1800
A10: Savings | B10: 5000
A11: Travel | B11: 2500

Sheet Analysis
A1: FINANCIAL ANALYSIS | SUMMARY TABLES
A3: Month | B3: Total Outflow (INR) | C3: Savings Contributions (INR) | E3: Category | F3: Transactions (INR) | G3: Budget (INR)
A4: 45658 | B4: =SUMIFS(Clean_Data!$I$2:$I$481,Clean_Data!$B$2:$B$481,">="&A4,Clean_Data!$B$2:$B$481,"<"&EDATE(A4,1),Clean_Data!$D$2:$D$481,"Expense") | C4: =SUMIFS(Clean_Data!$I$2:$I$481,Clean_Data!$B$2:$B$481,">="&A4,Clean_Data!$B$2:$B$481,"<"&EDATE(A4,1),Clean_Data!$D$2:$D$481,"Savings") | E4: Housing | F4: =SUMIFS(Clean_Data!$I$2:$I$481,Clean_Data!$E$2:$E$481,E4,Clean_Data!$D$2:$D$481,"Expense") | G4: =Budgets!$B$3
A5: 45689 | B5: =SUMIFS(Clean_Data!$I$2:$I$481,Clean_Data!$B$2:$B$481,">="&A5,Clean_Data!$B$2:$B$481,"<"&EDATE(A5,1),Clean_Data!$D$2:$D$481,"Expense") | C5: =SUMIFS(Clean_Data!$I$2:$I$481,Clean_Data!$B$2:$B$481,">="&A5,Clean_Data!$B$2:$B$481,"<"&EDATE(A5,1),Clean_Data!$D$2:$D$481,"Savings") | E5: Food | F5: =SUMIFS(Clean_Data!$I$2:$I$481,Clean_Data!$E$2:$E$481,E5,Clean_Data!$D$2:$D$481,"Expense") | G5: =Budgets!$B$4
A6: 45717 | B6: =SUMIFS(Clean_Data!$I$2:$I$481,Clean_Data!$B$2:$B$481,">="&A6,Clean_Data!$B$2:$B$481,"<"&EDATE(A6,1),Clean_Data!$D$2:$D$481,"Expense") | C6: =SUMIFS(Clean_Data!$I$2:$I$481,Clean_Data!$B$2:$B$481,">="&A6,Clean_Data!$B$2:$B$481,"<"&EDATE(A6,1),Clean_Data!$D$2:$D$481,"Savings") | E6: Transport | F6: =SUMIFS(Clean_Data!$I$2:$I$481,Clean_Data!$E$2:$E$481,E6,Clean_Data!$D$2:$D$481,"Expense") | G6: =Budgets!$B$5
A7: 45748 | B7: =SUMIFS(Clean_Data!$I$2:$I$481,Clean_Data!$B$2:$B$481,">="&A7,Clean_Data!$B$2:$B$481,"<"&EDATE(A7,1),Clean_Data!$D$2:$D$481,"Expense") | C7: =SUMIFS(Clean_Data!$I$2:$I$481,Clean_Data!$B$2:$B$481,">="&A7,Clean_Data!$B$2:$B$481,"<"&EDATE(A7,1),Clean_Data!$D$2:$D$481,"Savings") | E7: Utilities | F7: =SUMIFS(Clean_Data!$I$2:$I$481,Clean_Data!$E$2:$E$481,E7,Clean_Data!$D$2:$D$481,"Expense") | G7: =Budgets!$B$6
A8: 45778 | B8: =SUMIFS(Clean_Data!$I$2:$I$481,Clean_Data!$B$2:$B$481,">="&A8,Clean_Data!$B$2:$B$481,"<"&EDATE(A8,1),Clean_Data!$D$2:$D$481,"Expense") | C8: =SUMIFS(Clean_Data!$I$2:$I$481,Clean_Data!$B$2:$B$481,">="&A8,Clean_Data!$B$2:$B$481,"<"&EDATE(A8,1),Clean_Data!$D$2:$D$481,"Savings") | E8: Health | F8: =SUMIFS(Clean_Data!$I$2:$I$481,Clean_Data!$E$2:$E$481,E8,Clean_Data!$D$2:$D$481,"Expense") | G8: =Budgets!$B$7
A9: 45809 | B9: =SUMIFS(Clean_Data!$I$2:$I$481,Clean_Data!$B$2:$B$481,">="&A9,Clean_Data!$B$2:$B$481,"<"&EDATE(A9,1),Clean_Data!$D$2:$D$481,"Expense") | C9: =SUMIFS(Clean_Data!$I$2:$I$481,Clean_Data!$B$2:$B$481,">="&A9,Clean_Data!$B$2:$B$481,"<"&EDATE(A9,1),Clean_Data!$D$2:$D$481,"Savings") | E9: Shopping | F9: =SUMIFS(Clean_Data!$I$2:$I$481,Clean_Data!$E$2:$E$481,E9,Clean_Data!$D$2:$D$481,"Expense") | G9: =Budgets!$B$8
A10: 45839 | B10: =SUMIFS(Clean_Data!$I$2:$I$481,Clean_Data!$B$2:$B$481,">="&A10,Clean_Data!$B$2:$B$481,"<"&EDATE(A10,1),Clean_Data!$D$2:$D$481,"Expense") | C10: =SUMIFS(Clean_Data!$I$2:$I$481,Clean_Data!$B$2:$B$481,">="&A10,Clean_Data!$B$2:$B$481,"<"&EDATE(A10,1),Clean_Data!$D$2:$D$481,"Savings") | E10: Entertainment | F10: =SUMIFS(Clean_Data!$I$2:$I$481,Clean_Data!$E$2:$E$481,E10,Clean_Data!$D$2:$D$481,"Expense") | G10: =Budgets!$B$9
A11: 45870 | B11: =SUMIFS(Clean_Data!$I$2:$I$481,Clean_Data!$B$2:$B$481,">="&A11,Clean_Data!$B$2:$B$481,"<"&EDATE(A11,1),Clean_Data!$D$2:$D$481,"Expense") | C11: =SUMIFS(Clean_Data!$I$2:$I$481,Clean_Data!$B$2:$B$481,">="&A11,Clean_Data!$B$2:$B$481,"<"&EDATE(A11,1),Clean_Data!$D$2:$D$481,"Savings") | E11: Education | F11: =SUMIFS(Clean_Data!$I$2:$I$481,Clean_Data!$E$2:$E$481,E11,Clean_Data!$D$2:$D$481,"Expense") | G11: =Budgets!$B$10
A12: 45901 | B12: =SUMIFS(Clean_Data!$I$2:$I$481,Clean_Data!$B$2:$B$481,">="&A12,Clean_Data!$B$2:$B$481,"<"&EDATE(A12,1),Clean_Data!$D$2:$D$481,"Expense") | C12: =SUMIFS(Clean_Data!$I$2:$I$481,Clean_Data!$B$2:$B$481,">="&A12,Clean_Data!$B$2:$B$481,"<"&EDATE(A12,1),Clean_Data!$D$2:$D$481,"Savings") | E12: Savings | F12: =SUMIFS(Clean_Data!$I$2:$I$481,Clean_Data!$E$2:$E$481,E12,Clean_Data!$D$2:$D$481,"Expense") | G12: =Budgets!$B$11
A13: 45931 | B13: =SUMIFS(Clean_Data!$I$2:$I$481,Clean_Data!$B$2:$B$481,">="&A13,Clean_Data!$B$2:$B$481,"<"&EDATE(A13,1),Clean_Data!$D$2:$D$481,"Expense") | C13: =SUMIFS(Clean_Data!$I$2:$I$481,Clean_Data!$B$2:$B$481,">="&A13,Clean_Data!$B$2:$B$481,"<"&EDATE(A13,1),Clean_Data!$D$2:$D$481,"Savings") | E13: Travel | F13: =SUMIFS(Clean_Data!$I$2:$I$481,Clean_Data!$E$2:$E$481,E13,Clean_Data!$D$2:$D$481,"Expense") | G13: =Budgets!$B$12
A14: 45962 | B14: =SUMIFS(Clean_Data!$I$2:$I$481,Clean_Data!$B$2:$B$481,">="&A14,Clean_Data!$B$2:$B$481,"<"&EDATE(A14,1),Clean_Data!$D$2:$D$481,"Expense") | C14: =SUMIFS(Clean_Data!$I$2:$I$481,Clean_Data!$B$2:$B$481,">="&A14,Clean_Data!$B$2:$B$481,"<"&EDATE(A14,1),Clean_Data!$D$2:$D$481,"Savings")
A15: 45992 | B15: =SUMIFS(Clean_Data!$I$2:$I$481,Clean_Data!$B$2:$B$481,">="&A15,Clean_Data!$B$2:$B$481,"<"&EDATE(A15,1),Clean_Data!$D$2:$D$481,"Expense") | C15: =SUMIFS(Clean_Data!$I$2:$I$481,Clean_Data!$B$2:$B$481,">="&A15,Clean_Data!$B$2:$B$481,"<"&EDATE(A15,1),Clean_Data!$D$2:$D$481,"Savings")
E17: Payment Method | F17: Total Amount (INR)
E18: UPI | F18: =SUMIFS(Clean_Data!$I$2:$I$481,Clean_Data!$H$2:$H$481,E18)
E19: Debit Card | F19: =SUMIFS(Clean_Data!$I$2:$I$481,Clean_Data!$H$2:$H$481,E19)
E20: Credit Card | F20: =SUMIFS(Clean_Data!$I$2:$I$481,Clean_Data!$H$2:$H$481,E20)
E21: Cash | F21: =SUMIFS(Clean_Data!$I$2:$I$481,Clean_Data!$H$2:$H$481,E21)
E22: Bank Transfer | F22: =SUMIFS(Clean_Data!$I$2:$I$481,Clean_Data!$H$2:$H$481,E22)

Sheet Start_Here
A1: PROJECT GUIDE | FINANCIAL ANALYSIS
A4: Objective | B4: Analyze synthetic personal-finance transactions and compare spending patterns against category budgets.
A5: Dashboard | B5: Change Dashboard!B4 to All or a month to update KPI cards.
A6: Raw_Data | B6: Original synthetic transaction records preserved.
A7: Clean_Data | B7: Missing descriptions replaced with Not specified; text fields trimmed; budget and variance fields added.
A8: Budgets | B8: Monthly category budget assumptions used for practice.
A9: Analysis | B9: Formula-driven monthly, category and payment-method summaries.
A10: Important | B10: Synthetic educational data only; not personal financial advice.
A11: Budget interpretation | B11: Budget is a monthly category benchmark; a transaction above that benchmark is flagged for review, not proof that the monthly budget was exceeded.
